time 0ms: Simulator started for FCFS [Q <empty>]
time 0ms: Process A arrived and added to ready queue [Q A]
time 0ms: Process B arrived and added to ready queue [Q A B]
time 0ms: Process C arrived and added to ready queue [Q A B C]
time 0ms: Process X arrived and added to ready queue [Q A B C X]
time 0ms: Process Y arrived and added to ready queue [Q A B C X Y]
time 0ms: Process Z arrived and added to ready queue [Q A B C X Y Z]
time 4ms: Process A started using the CPU [Q B C X Y Z]
time 104ms: Process A completed a CPU burst; 3 bursts to go [Q B C X Y Z]
time 104ms: Process A switching out of CPU; will block on I/O until time 308ms [Q B C X Y Z]
time 112ms: Process B started using the CPU [Q C X Y Z]
time 213ms: Process B completed a CPU burst; 3 bursts to go [Q C X Y Z]
time 213ms: Process B switching out of CPU; will block on I/O until time 417ms [Q C X Y Z]
time 221ms: Process C started using the CPU [Q X Y Z]
time 308ms: Process A completed I/O; added to ready queue [Q X Y Z A]
time 323ms: Process C completed a CPU burst; 3 bursts to go [Q X Y Z A]
time 323ms: Process C switching out of CPU; will block on I/O until time 527ms [Q X Y Z A]
time 331ms: Process X started using the CPU [Q Y Z A]
time 417ms: Process B completed I/O; added to ready queue [Q Y Z A B]
time 434ms: Process X completed a CPU burst; 3 bursts to go [Q Y Z A B]
time 434ms: Process X switching out of CPU; will block on I/O until time 638ms [Q Y Z A B]
time 442ms: Process Y started using the CPU [Q Z A B]
time 527ms: Process C completed I/O; added to ready queue [Q Z A B C]
time 546ms: Process Y completed a CPU burst; 3 bursts to go [Q Z A B C]
time 546ms: Process Y switching out of CPU; will block on I/O until time 750ms [Q Z A B C]
time 554ms: Process Z started using the CPU [Q A B C]
time 638ms: Process X completed I/O; added to ready queue [Q A B C X]
time 659ms: Process Z completed a CPU burst; 3 bursts to go [Q A B C X]
time 659ms: Process Z switching out of CPU; will block on I/O until time 863ms [Q A B C X]
time 667ms: Process A started using the CPU [Q B C X]
time 750ms: Process Y completed I/O; added to ready queue [Q B C X Y]
time 767ms: Process A completed a CPU burst; 2 bursts to go [Q B C X Y]
time 767ms: Process A switching out of CPU; will block on I/O until time 971ms [Q B C X Y]
time 775ms: Process B started using the CPU [Q C X Y]
time 863ms: Process Z completed I/O; added to ready queue [Q C X Y Z]
time 876ms: Process B completed a CPU burst; 2 bursts to go [Q C X Y Z]
time 876ms: Process B switching out of CPU; will block on I/O until time 1080ms [Q C X Y Z]
time 884ms: Process C started using the CPU [Q X Y Z]
time 971ms: Process A completed I/O; added to ready queue [Q X Y Z A]
time 986ms: Process C completed a CPU burst; 2 bursts to go [Q X Y Z A]
time 986ms: Process C switching out of CPU; will block on I/O until time 1190ms [Q X Y Z A]
time 994ms: Process X started using the CPU [Q Y Z A]
time 1080ms: Process B completed I/O; added to ready queue [Q Y Z A B]
time 1097ms: Process X completed a CPU burst; 2 bursts to go [Q Y Z A B]
time 1097ms: Process X switching out of CPU; will block on I/O until time 1301ms [Q Y Z A B]
time 1105ms: Process Y started using the CPU [Q Z A B]
time 1190ms: Process C completed I/O; added to ready queue [Q Z A B C]
time 1209ms: Process Y completed a CPU burst; 2 bursts to go [Q Z A B C]
time 1209ms: Process Y switching out of CPU; will block on I/O until time 1413ms [Q Z A B C]
time 1217ms: Process Z started using the CPU [Q A B C]
time 1301ms: Process X completed I/O; added to ready queue [Q A B C X]
time 1322ms: Process Z completed a CPU burst; 2 bursts to go [Q A B C X]
time 1322ms: Process Z switching out of CPU; will block on I/O until time 1526ms [Q A B C X]
time 1330ms: Process A started using the CPU [Q B C X]
time 1413ms: Process Y completed I/O; added to ready queue [Q B C X Y]
time 1430ms: Process A completed a CPU burst; 1 burst to go [Q B C X Y]
time 1430ms: Process A switching out of CPU; will block on I/O until time 1634ms [Q B C X Y]
time 1438ms: Process B started using the CPU [Q C X Y]
time 1526ms: Process Z completed I/O; added to ready queue [Q C X Y Z]
time 1539ms: Process B completed a CPU burst; 1 burst to go [Q C X Y Z]
time 1539ms: Process B switching out of CPU; will block on I/O until time 1743ms [Q C X Y Z]
time 1547ms: Process C started using the CPU [Q X Y Z]
time 1634ms: Process A completed I/O; added to ready queue [Q X Y Z A]
time 1649ms: Process C completed a CPU burst; 1 burst to go [Q X Y Z A]
time 1649ms: Process C switching out of CPU; will block on I/O until time 1853ms [Q X Y Z A]
time 1657ms: Process X started using the CPU [Q Y Z A]
time 1743ms: Process B completed I/O; added to ready queue [Q Y Z A B]
time 1760ms: Process X completed a CPU burst; 1 burst to go [Q Y Z A B]
time 1760ms: Process X switching out of CPU; will block on I/O until time 1964ms [Q Y Z A B]
time 1768ms: Process Y started using the CPU [Q Z A B]
time 1853ms: Process C completed I/O; added to ready queue [Q Z A B C]
time 1872ms: Process Y completed a CPU burst; 1 burst to go [Q Z A B C]
time 1872ms: Process Y switching out of CPU; will block on I/O until time 2076ms [Q Z A B C]
time 1880ms: Process Z started using the CPU [Q A B C]
time 1964ms: Process X completed I/O; added to ready queue [Q A B C X]
time 1985ms: Process Z completed a CPU burst; 1 burst to go [Q A B C X]
time 1985ms: Process Z switching out of CPU; will block on I/O until time 2189ms [Q A B C X]
time 1993ms: Process A started using the CPU [Q B C X]
time 2076ms: Process Y completed I/O; added to ready queue [Q B C X Y]
time 2093ms: Process A terminated [Q B C X Y]
time 2101ms: Process B started using the CPU [Q C X Y]
time 2189ms: Process Z completed I/O; added to ready queue [Q C X Y Z]
time 2202ms: Process B terminated [Q C X Y Z]
time 2210ms: Process C started using the CPU [Q X Y Z]
time 2312ms: Process C terminated [Q X Y Z]
time 2320ms: Process X started using the CPU [Q Y Z]
time 2423ms: Process X terminated [Q Y Z]
time 2431ms: Process Y started using the CPU [Q Z]
time 2535ms: Process Y terminated [Q Z]
time 2543ms: Process Z started using the CPU [Q <empty>]
time 2648ms: Process Z terminated [Q <empty>]
time 2652ms: Simulator ended for FCFS

time 0ms: Simulator started for SRT [Q <empty>]
time 0ms: Process A arrived and added to ready queue [Q A]
time 0ms: Process B arrived and added to ready queue [Q A B]
time 0ms: Process C arrived and added to ready queue [Q A B C]
time 0ms: Process X arrived and added to ready queue [Q A B C X]
time 0ms: Process Y arrived and added to ready queue [Q A B C X Y]
time 0ms: Process Z arrived and added to ready queue [Q A B C X Y Z]
time 4ms: Process A started using the CPU [Q B C X Y Z]
time 104ms: Process A completed a CPU burst; 3 bursts to go [Q B C X Y Z]
time 104ms: Process A switching out of CPU; will block on I/O until time 308ms [Q B C X Y Z]
time 112ms: Process B started using the CPU [Q C X Y Z]
time 213ms: Process B completed a CPU burst; 3 bursts to go [Q C X Y Z]
time 213ms: Process B switching out of CPU; will block on I/O until time 417ms [Q C X Y Z]
time 221ms: Process C started using the CPU [Q X Y Z]
time 308ms: Process A completed I/O; added to ready queue [Q A X Y Z]
time 323ms: Process C completed a CPU burst; 3 bursts to go [Q A X Y Z]
time 323ms: Process C switching out of CPU; will block on I/O until time 527ms [Q A X Y Z]
time 331ms: Process A started using the CPU [Q X Y Z]
time 417ms: Process B completed I/O; added to ready queue [Q B X Y Z]
time 431ms: Process A completed a CPU burst; 2 bursts to go [Q B X Y Z]
time 431ms: Process A switching out of CPU; will block on I/O until time 635ms [Q B X Y Z]
time 439ms: Process B started using the CPU [Q X Y Z]
time 527ms: Process C completed I/O; added to ready queue [Q C X Y Z]
time 540ms: Process B completed a CPU burst; 2 bursts to go [Q C X Y Z]
time 540ms: Process B switching out of CPU; will block on I/O until time 744ms [Q C X Y Z]
time 548ms: Process C started using the CPU [Q X Y Z]
time 635ms: Process A completed I/O; added to ready queue [Q A X Y Z]
time 650ms: Process C completed a CPU burst; 2 bursts to go [Q A X Y Z]
time 650ms: Process C switching out of CPU; will block on I/O until time 854ms [Q A X Y Z]
time 658ms: Process A started using the CPU [Q X Y Z]
time 744ms: Process B completed I/O; added to ready queue [Q B X Y Z]
time 758ms: Process A completed a CPU burst; 1 burst to go [Q B X Y Z]
time 758ms: Process A switching out of CPU; will block on I/O until time 962ms [Q B X Y Z]
time 766ms: Process B started using the CPU [Q X Y Z]
time 854ms: Process C completed I/O; added to ready queue [Q C X Y Z]
time 867ms: Process B completed a CPU burst; 1 burst to go [Q C X Y Z]
time 867ms: Process B switching out of CPU; will block on I/O until time 1071ms [Q C X Y Z]
time 875ms: Process C started using the CPU [Q X Y Z]
time 962ms: Process A completed I/O; added to ready queue [Q A X Y Z]
time 977ms: Process C completed a CPU burst; 1 burst to go [Q A X Y Z]
time 977ms: Process C switching out of CPU; will block on I/O until time 1181ms [Q A X Y Z]
time 985ms: Process A started using the CPU [Q X Y Z]
time 1071ms: Process B completed I/O; added to ready queue [Q B X Y Z]
time 1085ms: Process A terminated [Q B X Y Z]
time 1093ms: Process B started using the CPU [Q X Y Z]
time 1181ms: Process C completed I/O; added to ready queue [Q C X Y Z]
time 1194ms: Process B terminated [Q C X Y Z]
time 1202ms: Process C started using the CPU [Q X Y Z]
time 1304ms: Process C terminated [Q X Y Z]
time 1312ms: Process X started using the CPU [Q Y Z]
time 1415ms: Process X completed a CPU burst; 3 bursts to go [Q Y Z]
time 1415ms: Process X switching out of CPU; will block on I/O until time 1619ms [Q Y Z]
time 1423ms: Process Y started using the CPU [Q Z]
time 1527ms: Process Y completed a CPU burst; 3 bursts to go [Q Z]
time 1527ms: Process Y switching out of CPU; will block on I/O until time 1731ms [Q Z]
time 1535ms: Process Z started using the CPU [Q <empty>]
time 1619ms: Process X completed I/O; added to ready queue [Q X]
time 1640ms: Process Z completed a CPU burst; 3 bursts to go [Q X]
time 1640ms: Process Z switching out of CPU; will block on I/O until time 1844ms [Q X]
time 1648ms: Process X started using the CPU [Q <empty>]
time 1731ms: Process Y completed I/O; added to ready queue [Q Y]
time 1751ms: Process X completed a CPU burst; 2 bursts to go [Q Y]
time 1751ms: Process X switching out of CPU; will block on I/O until time 1955ms [Q Y]
time 1759ms: Process Y started using the CPU [Q <empty>]
time 1844ms: Process Z completed I/O; added to ready queue [Q Z]
time 1863ms: Process Y completed a CPU burst; 2 bursts to go [Q Z]
time 1863ms: Process Y switching out of CPU; will block on I/O until time 2067ms [Q Z]
time 1871ms: Process Z started using the CPU [Q <empty>]
time 1955ms: Process X completed I/O; added to ready queue [Q X]
time 1976ms: Process Z completed a CPU burst; 2 bursts to go [Q X]
time 1976ms: Process Z switching out of CPU; will block on I/O until time 2180ms [Q X]
time 1984ms: Process X started using the CPU [Q <empty>]
time 2067ms: Process Y completed I/O; added to ready queue [Q Y]
time 2087ms: Process X completed a CPU burst; 1 burst to go [Q Y]
time 2087ms: Process X switching out of CPU; will block on I/O until time 2291ms [Q Y]
time 2095ms: Process Y started using the CPU [Q <empty>]
time 2180ms: Process Z completed I/O; added to ready queue [Q Z]
time 2199ms: Process Y completed a CPU burst; 1 burst to go [Q Z]
time 2199ms: Process Y switching out of CPU; will block on I/O until time 2403ms [Q Z]
time 2207ms: Process Z started using the CPU [Q <empty>]
time 2291ms: Process X completed I/O; added to ready queue [Q X]
time 2312ms: Process Z completed a CPU burst; 1 burst to go [Q X]
time 2312ms: Process Z switching out of CPU; will block on I/O until time 2516ms [Q X]
time 2320ms: Process X started using the CPU [Q <empty>]
time 2403ms: Process Y completed I/O; added to ready queue [Q Y]
time 2423ms: Process X terminated [Q Y]
time 2431ms: Process Y started using the CPU [Q <empty>]
time 2516ms: Process Z completed I/O; added to ready queue [Q Z]
time 2535ms: Process Y terminated [Q Z]
time 2543ms: Process Z started using the CPU [Q <empty>]
time 2648ms: Process Z terminated [Q <empty>]
time 2652ms: Simulator ended for SRT

time 0ms: Simulator started for RR [Q <empty>]
time 0ms: Process A arrived and added to ready queue [Q A]
time 0ms: Process B arrived and added to ready queue [Q A B]
time 0ms: Process C arrived and added to ready queue [Q A B C]
time 0ms: Process X arrived and added to ready queue [Q A B C X]
time 0ms: Process Y arrived and added to ready queue [Q A B C X Y]
time 0ms: Process Z arrived and added to ready queue [Q A B C X Y Z]
time 4ms: Process A started using the CPU [Q B C X Y Z]
time 74ms: Time slice expired; process A preempted with 30ms to go [Q B C X Y Z]
time 82ms: Process B started using the CPU [Q C X Y Z A]
time 152ms: Time slice expired; process B preempted with 31ms to go [Q C X Y Z A]
time 160ms: Process C started using the CPU [Q X Y Z A B]
time 230ms: Time slice expired; process C preempted with 32ms to go [Q X Y Z A B]
time 238ms: Process X started using the CPU [Q Y Z A B C]
time 308ms: Time slice expired; process X preempted with 33ms to go [Q Y Z A B C]
time 316ms: Process Y started using the CPU [Q Z A B C X]
time 386ms: Time slice expired; process Y preempted with 34ms to go [Q Z A B C X]
time 394ms: Process Z started using the CPU [Q A B C X Y]
time 464ms: Time slice expired; process Z preempted with 35ms to go [Q A B C X Y]
time 472ms: Process A started using the CPU with 30ms remaining [Q B C X Y Z]
time 502ms: Process A completed a CPU burst; 3 bursts to go [Q B C X Y Z]
time 502ms: Process A switching out of CPU; will block on I/O until time 706ms [Q B C X Y Z]
time 510ms: Process B started using the CPU with 31ms remaining [Q C X Y Z]
time 541ms: Process B completed a CPU burst; 3 bursts to go [Q C X Y Z]
time 541ms: Process B switching out of CPU; will block on I/O until time 745ms [Q C X Y Z]
time 549ms: Process C started using the CPU with 32ms remaining [Q X Y Z]
time 581ms: Process C completed a CPU burst; 3 bursts to go [Q X Y Z]
time 581ms: Process C switching out of CPU; will block on I/O until time 785ms [Q X Y Z]
time 589ms: Process X started using the CPU with 33ms remaining [Q Y Z]
time 622ms: Process X completed a CPU burst; 3 bursts to go [Q Y Z]
time 622ms: Process X switching out of CPU; will block on I/O until time 826ms [Q Y Z]
time 630ms: Process Y started using the CPU with 34ms remaining [Q Z]
time 664ms: Process Y completed a CPU burst; 3 bursts to go [Q Z]
time 664ms: Process Y switching out of CPU; will block on I/O until time 868ms [Q Z]
time 672ms: Process Z started using the CPU with 35ms remaining [Q <empty>]
time 706ms: Process A completed I/O; added to ready queue [Q A]
time 707ms: Process Z completed a CPU burst; 3 bursts to go [Q A]
time 707ms: Process Z switching out of CPU; will block on I/O until time 911ms [Q A]
time 715ms: Process A started using the CPU [Q <empty>]
time 745ms: Process B completed I/O; added to ready queue [Q B]
time 785ms: Time slice expired; process A preempted with 30ms to go [Q B]
time 785ms: Process C completed I/O; added to ready queue [Q B A C]
time 793ms: Process B started using the CPU [Q A C]
time 826ms: Process X completed I/O; added to ready queue [Q A C X]
time 863ms: Time slice expired; process B preempted with 31ms to go [Q A C X]
time 868ms: Process Y completed I/O; added to ready queue [Q C X B Y]
time 871ms: Process A started using the CPU with 30ms remaining [Q C X B Y]
time 901ms: Process A completed a CPU burst; 2 bursts to go [Q C X B Y]
time 901ms: Process A switching out of CPU; will block on I/O until time 1105ms [Q C X B Y]
time 909ms: Process C started using the CPU [Q X B Y]
time 911ms: Process Z completed I/O; added to ready queue [Q X B Y Z]
time 979ms: Time slice expired; process C preempted with 32ms to go [Q X B Y Z]
time 987ms: Process X started using the CPU [Q B Y Z C]
time 1057ms: Time slice expired; process X preempted with 33ms to go [Q B Y Z C]
time 1065ms: Process B started using the CPU with 31ms remaining [Q Y Z C X]
time 1096ms: Process B completed a CPU burst; 2 bursts to go [Q Y Z C X]
time 1096ms: Process B switching out of CPU; will block on I/O until time 1300ms [Q Y Z C X]
time 1104ms: Process Y started using the CPU [Q Z C X]
time 1105ms: Process A completed I/O; added to ready queue [Q Z C X A]
time 1174ms: Time slice expired; process Y preempted with 34ms to go [Q Z C X A]
time 1182ms: Process Z started using the CPU [Q C X A Y]
time 1252ms: Time slice expired; process Z preempted with 35ms to go [Q C X A Y]
time 1260ms: Process C started using the CPU with 32ms remaining [Q X A Y Z]
time 1292ms: Process C completed a CPU burst; 2 bursts to go [Q X A Y Z]
time 1292ms: Process C switching out of CPU; will block on I/O until time 1496ms [Q X A Y Z]
time 1300ms: Process X started using the CPU with 33ms remaining [Q A Y Z]
time 1300ms: Process B completed I/O; added to ready queue [Q A Y Z B]
time 1333ms: Process X completed a CPU burst; 2 bursts to go [Q A Y Z B]
time 1333ms: Process X switching out of CPU; will block on I/O until time 1537ms [Q A Y Z B]
time 1341ms: Process A started using the CPU [Q Y Z B]
time 1411ms: Time slice expired; process A preempted with 30ms to go [Q Y Z B]
time 1419ms: Process Y started using the CPU with 34ms remaining [Q Z B A]
time 1453ms: Process Y completed a CPU burst; 2 bursts to go [Q Z B A]
time 1453ms: Process Y switching out of CPU; will block on I/O until time 1657ms [Q Z B A]
time 1461ms: Process Z started using the CPU with 35ms remaining [Q B A]
time 1496ms: Process Z completed a CPU burst; 2 bursts to go [Q B A]
time 1496ms: Process Z switching out of CPU; will block on I/O until time 1700ms [Q B A]
time 1496ms: Process C completed I/O; added to ready queue [Q B A C]
time 1504ms: Process B started using the CPU [Q A C]
time 1537ms: Process X completed I/O; added to ready queue [Q A C X]
time 1574ms: Time slice expired; process B preempted with 31ms to go [Q A C X]
time 1582ms: Process A started using the CPU with 30ms remaining [Q C X B]
time 1612ms: Process A completed a CPU burst; 1 burst to go [Q C X B]
time 1612ms: Process A switching out of CPU; will block on I/O until time 1816ms [Q C X B]
time 1620ms: Process C started using the CPU [Q X B]
time 1657ms: Process Y completed I/O; added to ready queue [Q X B Y]
time 1690ms: Time slice expired; process C preempted with 32ms to go [Q X B Y]
time 1698ms: Process X started using the CPU [Q B Y C]
time 1700ms: Process Z completed I/O; added to ready queue [Q B Y C Z]
time 1768ms: Time slice expired; process X preempted with 33ms to go [Q B Y C Z]
time 1776ms: Process B started using the CPU with 31ms remaining [Q Y C Z X]
time 1807ms: Process B completed a CPU burst; 1 burst to go [Q Y C Z X]
time 1807ms: Process B switching out of CPU; will block on I/O until time 2011ms [Q Y C Z X]
time 1815ms: Process Y started using the CPU [Q C Z X]
time 1816ms: Process A completed I/O; added to ready queue [Q C Z X A]
time 1885ms: Time slice expired; process Y preempted with 34ms to go [Q C Z X A]
time 1893ms: Process C started using the CPU with 32ms remaining [Q Z X A Y]
time 1925ms: Process C completed a CPU burst; 1 burst to go [Q Z X A Y]
time 1925ms: Process C switching out of CPU; will block on I/O until time 2129ms [Q Z X A Y]
time 1933ms: Process Z started using the CPU [Q X A Y]
time 2003ms: Time slice expired; process Z preempted with 35ms to go [Q X A Y]
time 2011ms: Process X started using the CPU with 33ms remaining [Q A Y Z]
time 2011ms: Process B completed I/O; added to ready queue [Q A Y Z B]
time 2044ms: Process X completed a CPU burst; 1 burst to go [Q A Y Z B]
time 2044ms: Process X switching out of CPU; will block on I/O until time 2248ms [Q A Y Z B]
time 2052ms: Process A started using the CPU [Q Y Z B]
time 2122ms: Time slice expired; process A preempted with 30ms to go [Q Y Z B]
time 2129ms: Process C completed I/O; added to ready queue [Q Z B A C]
time 2130ms: Process Y started using the CPU with 34ms remaining [Q Z B A C]
time 2164ms: Process Y completed a CPU burst; 1 burst to go [Q Z B A C]
time 2164ms: Process Y switching out of CPU; will block on I/O until time 2368ms [Q Z B A C]
time 2172ms: Process Z started using the CPU with 35ms remaining [Q B A C]
time 2207ms: Process Z completed a CPU burst; 1 burst to go [Q B A C]
time 2207ms: Process Z switching out of CPU; will block on I/O until time 2411ms [Q B A C]
time 2215ms: Process B started using the CPU [Q A C]
time 2248ms: Process X completed I/O; added to ready queue [Q A C X]
time 2285ms: Time slice expired; process B preempted with 31ms to go [Q A C X]
time 2293ms: Process A started using the CPU with 30ms remaining [Q C X B]
time 2323ms: Process A terminated [Q C X B]
time 2331ms: Process C started using the CPU [Q X B]
time 2368ms: Process Y completed I/O; added to ready queue [Q X B Y]
time 2401ms: Time slice expired; process C preempted with 32ms to go [Q X B Y]
time 2409ms: Process X started using the CPU [Q B Y C]
time 2411ms: Process Z completed I/O; added to ready queue [Q B Y C Z]
time 2479ms: Time slice expired; process X preempted with 33ms to go [Q B Y C Z]
time 2487ms: Process B started using the CPU with 31ms remaining [Q Y C Z X]
time 2518ms: Process B terminated [Q Y C Z X]
time 2526ms: Process Y started using the CPU [Q C Z X]
time 2596ms: Time slice expired; process Y preempted with 34ms to go [Q C Z X]
time 2604ms: Process C started using the CPU with 32ms remaining [Q Z X Y]
time 2636ms: Process C terminated [Q Z X Y]
time 2644ms: Process Z started using the CPU [Q X Y]
time 2714ms: Time slice expired; process Z preempted with 35ms to go [Q X Y]
time 2722ms: Process X started using the CPU with 33ms remaining [Q Y Z]
time 2755ms: Process X terminated [Q Y Z]
time 2763ms: Process Y started using the CPU with 34ms remaining [Q Z]
time 2797ms: Process Y terminated [Q Z]
time 2805ms: Process Z started using the CPU with 35ms remaining [Q <empty>]
time 2840ms: Process Z terminated [Q <empty>]
time 2844ms: Simulator ended for RR
